Traceback (most recent call last):
  File "/usr/share/miniconda/envs/test/lib/python3.11/site-packages/jupyter_cache/executors/utils.py", line 51, in single_nb_execution
    executenb(
  File "/usr/share/miniconda/envs/test/lib/python3.11/site-packages/nbclient/client.py", line 1204, in execute
    return NotebookClient(nb=nb, resources=resources, km=km, **kwargs).execute()
           ^^^^^^^^^^^^^^^^^^^^^^^^^^^^^^^^^^^^^^^^^^^^^^^^^^^^^^^^^^^^^^^^^^^^^
  File "/usr/share/miniconda/envs/test/lib/python3.11/site-packages/nbclient/util.py", line 84, in wrapped
    return just_run(coro(*args, **kwargs))
           ^^^^^^^^^^^^^^^^^^^^^^^^^^^^^^^
  File "/usr/share/miniconda/envs/test/lib/python3.11/site-packages/nbclient/util.py", line 62, in just_run
    return loop.run_until_complete(coro)
           ^^^^^^^^^^^^^^^^^^^^^^^^^^^^^
  File "/usr/share/miniconda/envs/test/lib/python3.11/asyncio/base_events.py", line 654, in run_until_complete
    return future.result()
           ^^^^^^^^^^^^^^^
  File "/usr/share/miniconda/envs/test/lib/python3.11/site-packages/nbclient/client.py", line 663, in async_execute
    await self.async_execute_cell(
  File "/usr/share/miniconda/envs/test/lib/python3.11/site-packages/nbclient/client.py", line 965, in async_execute_cell
    await self._check_raise_for_error(cell, cell_index, exec_reply)
  File "/usr/share/miniconda/envs/test/lib/python3.11/site-packages/nbclient/client.py", line 862, in _check_raise_for_error
    raise CellExecutionError.from_cell_and_msg(cell, exec_reply_content)
nbclient.exceptions.CellExecutionError: An error occurred while executing the following cell:
------------------
plt.style.use('../photutils_notebook_style.mplstyle')
------------------

[0;31m---------------------------------------------------------------------------[0m
[0;31mFileNotFoundError[0m                         Traceback (most recent call last)
File [0;32m/usr/share/miniconda/envs/test/lib/python3.11/site-packages/matplotlib/style/core.py:137[0m, in [0;36muse[0;34m(style)[0m
[1;32m    136[0m [38;5;28;01mtry[39;00m:
[0;32m--> 137[0m     style [38;5;241m=[39m [43m_rc_params_in_file[49m[43m([49m[43mstyle[49m[43m)[49m
[1;32m    138[0m [38;5;28;01mexcept[39;00m [38;5;167;01mOSError[39;00m [38;5;28;01mas[39;00m err:

File [0;32m/usr/share/miniconda/envs/test/lib/python3.11/site-packages/matplotlib/__init__.py:866[0m, in [0;36m_rc_params_in_file[0;34m(fname, transform, fail_on_error)[0m
[1;32m    865[0m rc_temp [38;5;241m=[39m {}
[0;32m--> 866[0m [43m[49m[38;5;28;43;01mwith[39;49;00m[43m [49m[43m_open_file_or_url[49m[43m([49m[43mfname[49m[43m)[49m[43m [49m[38;5;28;43;01mas[39;49;00m[43m [49m[43mfd[49m[43m:[49m
[1;32m    867[0m [43m    [49m[38;5;28;43;01mtry[39;49;00m[43m:[49m

File [0;32m/usr/share/miniconda/envs/test/lib/python3.11/contextlib.py:137[0m, in [0;36m_GeneratorContextManager.__enter__[0;34m(self)[0m
[1;32m    136[0m [38;5;28;01mtry[39;00m:
[0;32m--> 137[0m     [38;5;28;01mreturn[39;00m [38;5;28mnext[39m([38;5;28mself[39m[38;5;241m.[39mgen)
[1;32m    138[0m [38;5;28;01mexcept[39;00m [38;5;167;01mStopIteration[39;00m:

File [0;32m/usr/share/miniconda/envs/test/lib/python3.11/site-packages/matplotlib/__init__.py:843[0m, in [0;36m_open_file_or_url[0;34m(fname)[0m
[1;32m    842[0m fname [38;5;241m=[39m os[38;5;241m.[39mpath[38;5;241m.[39mexpanduser(fname)
[0;32m--> 843[0m [38;5;28;01mwith[39;00m [38;5;28mopen[39m(fname, encoding[38;5;241m=[39m[38;5;124m'[39m[38;5;124mutf-8[39m[38;5;124m'[39m) [38;5;28;01mas[39;00m f:
[1;32m    844[0m     [38;5;28;01myield[39;00m f

[0;31mFileNotFoundError[0m: [Errno 2] No such file or directory: '../photutils_notebook_style.mplstyle'

The above exception was the direct cause of the following exception:

[0;31mOSError[0m                                   Traceback (most recent call last)
Cell [0;32mIn[2], line 1[0m
[0;32m----> 1[0m [43mplt[49m[38;5;241;43m.[39;49m[43mstyle[49m[38;5;241;43m.[39;49m[43muse[49m[43m([49m[38;5;124;43m'[39;49m[38;5;124;43m../photutils_notebook_style.mplstyle[39;49m[38;5;124;43m'[39;49m[43m)[49m

File [0;32m/usr/share/miniconda/envs/test/lib/python3.11/site-packages/matplotlib/style/core.py:139[0m, in [0;36muse[0;34m(style)[0m
[1;32m    137[0m         style [38;5;241m=[39m _rc_params_in_file(style)
[1;32m    138[0m     [38;5;28;01mexcept[39;00m [38;5;167;01mOSError[39;00m [38;5;28;01mas[39;00m err:
[0;32m--> 139[0m         [38;5;28;01mraise[39;00m [38;5;167;01mOSError[39;00m(
[1;32m    140[0m             [38;5;124mf[39m[38;5;124m"[39m[38;5;132;01m{[39;00mstyle[38;5;132;01m!r}[39;00m[38;5;124m is not a valid package style, path of style [39m[38;5;124m"[39m
[1;32m    141[0m             [38;5;124mf[39m[38;5;124m"[39m[38;5;124mfile, URL of style file, or library style name (library [39m[38;5;124m"[39m
[1;32m    142[0m             [38;5;124mf[39m[38;5;124m"[39m[38;5;124mstyles are listed in `style.available`)[39m[38;5;124m"[39m) [38;5;28;01mfrom[39;00m [38;5;21;01merr[39;00m
[1;32m    143[0m filtered [38;5;241m=[39m {}
[1;32m    144[0m [38;5;28;01mfor[39;00m k [38;5;129;01min[39;00m style:  [38;5;66;03m# don't trigger RcParams.__getitem__('backend')[39;00m

[0;31mOSError[0m: '../photutils_notebook_style.mplstyle' is not a valid package style, path of style file, URL of style file, or library style name (library styles are listed in `style.available`)
OSError: '../photutils_notebook_style.mplstyle' is not a valid package style, path of style file, URL of style file, or library style name (library styles are listed in `style.available`)

