Traceback (most recent call last):
  File "/usr/share/miniconda/envs/test/lib/python3.11/site-packages/jupyter_cache/executors/utils.py", line 51, in single_nb_execution
    executenb(
  File "/usr/share/miniconda/envs/test/lib/python3.11/site-packages/nbclient/client.py", line 1204, in execute
    return NotebookClient(nb=nb, resources=resources, km=km, **kwargs).execute()
           ^^^^^^^^^^^^^^^^^^^^^^^^^^^^^^^^^^^^^^^^^^^^^^^^^^^^^^^^^^^^^^^^^^^^^
  File "/usr/share/miniconda/envs/test/lib/python3.11/site-packages/nbclient/util.py", line 84, in wrapped
    return just_run(coro(*args, **kwargs))
           ^^^^^^^^^^^^^^^^^^^^^^^^^^^^^^^
  File "/usr/share/miniconda/envs/test/lib/python3.11/site-packages/nbclient/util.py", line 62, in just_run
    return loop.run_until_complete(coro)
           ^^^^^^^^^^^^^^^^^^^^^^^^^^^^^
  File "/usr/share/miniconda/envs/test/lib/python3.11/asyncio/base_events.py", line 653, in run_until_complete
    return future.result()
           ^^^^^^^^^^^^^^^
  File "/usr/share/miniconda/envs/test/lib/python3.11/site-packages/nbclient/client.py", line 663, in async_execute
    await self.async_execute_cell(
  File "/usr/share/miniconda/envs/test/lib/python3.11/site-packages/nbclient/client.py", line 965, in async_execute_cell
    await self._check_raise_for_error(cell, cell_index, exec_reply)
  File "/usr/share/miniconda/envs/test/lib/python3.11/site-packages/nbclient/client.py", line 862, in _check_raise_for_error
    raise CellExecutionError.from_cell_and_msg(cell, exec_reply_content)
nbclient.exceptions.CellExecutionError: An error occurred while executing the following cell:
------------------
calibrated_images = Path('.')
combined_dark_lfc = CCDData.read(calibrated_images / 'combined_dark_300.000.fits.bz2')
------------------

[0;31m---------------------------------------------------------------------------[0m
[0;31mFileNotFoundError[0m                         Traceback (most recent call last)
Cell [0;32mIn[3], line 2[0m
[1;32m      1[0m calibrated_images [38;5;241m=[39m Path([38;5;124m'[39m[38;5;124m.[39m[38;5;124m'[39m)
[0;32m----> 2[0m combined_dark_lfc [38;5;241m=[39m [43mCCDData[49m[38;5;241;43m.[39;49m[43mread[49m[43m([49m[43mcalibrated_images[49m[43m [49m[38;5;241;43m/[39;49m[43m [49m[38;5;124;43m'[39;49m[38;5;124;43mcombined_dark_300.000.fits.bz2[39;49m[38;5;124;43m'[39;49m[43m)[49m

File [0;32m/usr/share/miniconda/envs/test/lib/python3.11/site-packages/astropy/nddata/mixins/ndio.py:59[0m, in [0;36mNDDataRead.__call__[0;34m(self, *args, **kwargs)[0m
[1;32m     58[0m [38;5;28;01mdef[39;00m [38;5;21m__call__[39m([38;5;28mself[39m, [38;5;241m*[39margs, [38;5;241m*[39m[38;5;241m*[39mkwargs):
[0;32m---> 59[0m     [38;5;28;01mreturn[39;00m [38;5;28;43mself[39;49m[38;5;241;43m.[39;49m[43mregistry[49m[38;5;241;43m.[39;49m[43mread[49m[43m([49m[38;5;28;43mself[39;49m[38;5;241;43m.[39;49m[43m_cls[49m[43m,[49m[43m [49m[38;5;241;43m*[39;49m[43margs[49m[43m,[49m[43m [49m[38;5;241;43m*[39;49m[38;5;241;43m*[39;49m[43mkwargs[49m[43m)[49m

File [0;32m/usr/share/miniconda/envs/test/lib/python3.11/site-packages/astropy/io/registry/core.py:200[0m, in [0;36mUnifiedInputRegistry.read[0;34m(self, cls, format, cache, *args, **kwargs)[0m
[1;32m    196[0m [38;5;28;01mtry[39;00m:
[1;32m    197[0m     ctx [38;5;241m=[39m get_readable_fileobj(
[1;32m    198[0m         args[[38;5;241m0[39m], encoding[38;5;241m=[39m[38;5;124m"[39m[38;5;124mbinary[39m[38;5;124m"[39m, cache[38;5;241m=[39mcache
[1;32m    199[0m     )
[0;32m--> 200[0m     fileobj [38;5;241m=[39m [43mctx[49m[38;5;241;43m.[39;49m[38;5;21;43m__enter__[39;49m[43m([49m[43m)[49m
[1;32m    201[0m [38;5;28;01mexcept[39;00m [38;5;167;01mOSError[39;00m:
[1;32m    202[0m     [38;5;28;01mraise[39;00m

File [0;32m/usr/share/miniconda/envs/test/lib/python3.11/contextlib.py:137[0m, in [0;36m_GeneratorContextManager.__enter__[0;34m(self)[0m
[1;32m    135[0m [38;5;28;01mdel[39;00m [38;5;28mself[39m[38;5;241m.[39margs, [38;5;28mself[39m[38;5;241m.[39mkwds, [38;5;28mself[39m[38;5;241m.[39mfunc
[1;32m    136[0m [38;5;28;01mtry[39;00m:
[0;32m--> 137[0m     [38;5;28;01mreturn[39;00m [38;5;28mnext[39m([38;5;28mself[39m[38;5;241m.[39mgen)
[1;32m    138[0m [38;5;28;01mexcept[39;00m [38;5;167;01mStopIteration[39;00m:
[1;32m    139[0m     [38;5;28;01mraise[39;00m [38;5;167;01mRuntimeError[39;00m([38;5;124m"[39m[38;5;124mgenerator didn[39m[38;5;124m'[39m[38;5;124mt yield[39m[38;5;124m"[39m) [38;5;28;01mfrom[39;00m [38;5;28;01mNone[39;00m

File [0;32m/usr/share/miniconda/envs/test/lib/python3.11/site-packages/astropy/utils/data.py:364[0m, in [0;36mget_readable_fileobj[0;34m(name_or_obj, encoding, cache, show_progress, remote_timeout, sources, http_headers, use_fsspec, fsspec_kwargs, close_files)[0m
[1;32m    355[0m [38;5;28;01mif[39;00m is_url:
[1;32m    356[0m     name_or_obj [38;5;241m=[39m download_file(
[1;32m    357[0m         name_or_obj,
[1;32m    358[0m         cache[38;5;241m=[39mcache,
[0;32m   (...)[0m
[1;32m    362[0m         http_headers[38;5;241m=[39mhttp_headers,
[1;32m    363[0m     )
[0;32m--> 364[0m fileobj [38;5;241m=[39m [43mio[49m[38;5;241;43m.[39;49m[43mFileIO[49m[43m([49m[43mname_or_obj[49m[43m,[49m[43m [49m[38;5;124;43m"[39;49m[38;5;124;43mr[39;49m[38;5;124;43m"[39;49m[43m)[49m
[1;32m    365[0m [38;5;28;01mif[39;00m is_url [38;5;129;01mand[39;00m [38;5;129;01mnot[39;00m cache:
[1;32m    366[0m     delete_fds[38;5;241m.[39mappend(fileobj)

[0;31mFileNotFoundError[0m: [Errno 2] No such file or directory: 'combined_dark_300.000.fits.bz2'
FileNotFoundError: [Errno 2] No such file or directory: 'combined_dark_300.000.fits.bz2'

