Traceback (most recent call last):
  File "/home/runner/miniconda3/envs/mamba/lib/python3.11/site-packages/jupyter_cache/executors/utils.py", line 51, in single_nb_execution
    executenb(
  File "/home/runner/miniconda3/envs/mamba/lib/python3.11/site-packages/nbclient/client.py", line 1204, in execute
    return NotebookClient(nb=nb, resources=resources, km=km, **kwargs).execute()
           ^^^^^^^^^^^^^^^^^^^^^^^^^^^^^^^^^^^^^^^^^^^^^^^^^^^^^^^^^^^^^^^^^^^^^
  File "/home/runner/miniconda3/envs/mamba/lib/python3.11/site-packages/nbclient/util.py", line 84, in wrapped
    return just_run(coro(*args, **kwargs))
           ^^^^^^^^^^^^^^^^^^^^^^^^^^^^^^^
  File "/home/runner/miniconda3/envs/mamba/lib/python3.11/site-packages/nbclient/util.py", line 62, in just_run
    return loop.run_until_complete(coro)
           ^^^^^^^^^^^^^^^^^^^^^^^^^^^^^
  File "/home/runner/miniconda3/envs/mamba/lib/python3.11/asyncio/base_events.py", line 654, in run_until_complete
    return future.result()
           ^^^^^^^^^^^^^^^
  File "/home/runner/miniconda3/envs/mamba/lib/python3.11/site-packages/nbclient/client.py", line 663, in async_execute
    await self.async_execute_cell(
  File "/home/runner/miniconda3/envs/mamba/lib/python3.11/site-packages/nbclient/client.py", line 965, in async_execute_cell
    await self._check_raise_for_error(cell, cell_index, exec_reply)
  File "/home/runner/miniconda3/envs/mamba/lib/python3.11/site-packages/nbclient/client.py", line 862, in _check_raise_for_error
    raise CellExecutionError.from_cell_and_msg(cell, exec_reply_content)
nbclient.exceptions.CellExecutionError: An error occurred while executing the following cell:
------------------
from pathlib import Path

import numpy as np
from matplotlib import pyplot as plt

from astropy.nddata import CCDData
from astropy.nddata import block_replicate
from astropy import units as u
import ccdproc as ccdp
from photutils import detect_sources

from convenience_functions import show_image, display_cosmic_rays
------------------

[31m---------------------------------------------------------------------------[39m
[31mImportError[39m                               Traceback (most recent call last)
[36mCell[39m[36m [39m[32mIn[1][39m[32m, line 10[39m
[32m      8[39m [38;5;28;01mfrom[39;00m[38;5;250m [39m[34;01mastropy[39;00m[38;5;250m [39m[38;5;28;01mimport[39;00m units [38;5;28;01mas[39;00m u
[32m      9[39m [38;5;28;01mimport[39;00m[38;5;250m [39m[34;01mccdproc[39;00m[38;5;250m [39m[38;5;28;01mas[39;00m[38;5;250m [39m[34;01mccdp[39;00m
[32m---> [39m[32m10[39m [38;5;28;01mfrom[39;00m[38;5;250m [39m[34;01mphotutils[39;00m[38;5;250m [39m[38;5;28;01mimport[39;00m detect_sources
[32m     12[39m [38;5;28;01mfrom[39;00m[38;5;250m [39m[34;01mconvenience_functions[39;00m[38;5;250m [39m[38;5;28;01mimport[39;00m show_image, display_cosmic_rays

[31mImportError[39m: cannot import name 'detect_sources' from 'photutils' (/home/runner/miniconda3/envs/mamba/lib/python3.11/site-packages/photutils/__init__.py)
ImportError: cannot import name 'detect_sources' from 'photutils' (/home/runner/miniconda3/envs/mamba/lib/python3.11/site-packages/photutils/__init__.py)

