Traceback (most recent call last):
  File "/usr/share/miniconda/envs/test/lib/python3.11/site-packages/jupyter_cache/executors/utils.py", line 51, in single_nb_execution
    executenb(
  File "/usr/share/miniconda/envs/test/lib/python3.11/site-packages/nbclient/client.py", line 1204, in execute
    return NotebookClient(nb=nb, resources=resources, km=km, **kwargs).execute()
           ^^^^^^^^^^^^^^^^^^^^^^^^^^^^^^^^^^^^^^^^^^^^^^^^^^^^^^^^^^^^^^^^^^^^^
  File "/usr/share/miniconda/envs/test/lib/python3.11/site-packages/nbclient/util.py", line 84, in wrapped
    return just_run(coro(*args, **kwargs))
           ^^^^^^^^^^^^^^^^^^^^^^^^^^^^^^^
  File "/usr/share/miniconda/envs/test/lib/python3.11/site-packages/nbclient/util.py", line 62, in just_run
    return loop.run_until_complete(coro)
           ^^^^^^^^^^^^^^^^^^^^^^^^^^^^^
  File "/usr/share/miniconda/envs/test/lib/python3.11/asyncio/base_events.py", line 654, in run_until_complete
    return future.result()
           ^^^^^^^^^^^^^^^
  File "/usr/share/miniconda/envs/test/lib/python3.11/site-packages/nbclient/client.py", line 663, in async_execute
    await self.async_execute_cell(
  File "/usr/share/miniconda/envs/test/lib/python3.11/site-packages/nbclient/client.py", line 965, in async_execute_cell
    await self._check_raise_for_error(cell, cell_index, exec_reply)
  File "/usr/share/miniconda/envs/test/lib/python3.11/site-packages/nbclient/client.py", line 862, in _check_raise_for_error
    raise CellExecutionError.from_cell_and_msg(cell, exec_reply_content)
nbclient.exceptions.CellExecutionError: An error occurred while executing the following cell:
------------------
from pathlib import Path

import numpy as np
import matplotlib.pyplot as plt

from astropy import units as u
from astropy.nddata import CCDData

import ccdproc as ccdp
from photutils import detect_sources

from convenience_functions import show_image, image_snippet
------------------

[0;31m---------------------------------------------------------------------------[0m
[0;31mImportError[0m                               Traceback (most recent call last)
Cell [0;32mIn[1], line 10[0m
[1;32m      7[0m [38;5;28;01mfrom[39;00m [38;5;21;01mastropy[39;00m[38;5;21;01m.[39;00m[38;5;21;01mnddata[39;00m [38;5;28;01mimport[39;00m CCDData
[1;32m      9[0m [38;5;28;01mimport[39;00m [38;5;21;01mccdproc[39;00m [38;5;28;01mas[39;00m [38;5;21;01mccdp[39;00m
[0;32m---> 10[0m [38;5;28;01mfrom[39;00m [38;5;21;01mphotutils[39;00m [38;5;28;01mimport[39;00m detect_sources
[1;32m     12[0m [38;5;28;01mfrom[39;00m [38;5;21;01mconvenience_functions[39;00m [38;5;28;01mimport[39;00m show_image, image_snippet

[0;31mImportError[0m: cannot import name 'detect_sources' from 'photutils' (/usr/share/miniconda/envs/test/lib/python3.11/site-packages/photutils/__init__.py)
ImportError: cannot import name 'detect_sources' from 'photutils' (/usr/share/miniconda/envs/test/lib/python3.11/site-packages/photutils/__init__.py)

